[2022-10-26 11:30:08,593] {taskinstance.py:1159} INFO - Dependencies all met for <TaskInstance: dag.load_group_log scheduled__2022-10-26T11:15:00+00:00 [queued]>
[2022-10-26 11:30:08,600] {taskinstance.py:1159} INFO - Dependencies all met for <TaskInstance: dag.load_group_log scheduled__2022-10-26T11:15:00+00:00 [queued]>
[2022-10-26 11:30:08,600] {taskinstance.py:1356} INFO - 
--------------------------------------------------------------------------------
[2022-10-26 11:30:08,601] {taskinstance.py:1357} INFO - Starting attempt 1 of 1
[2022-10-26 11:30:08,601] {taskinstance.py:1358} INFO - 
--------------------------------------------------------------------------------
[2022-10-26 11:30:08,613] {taskinstance.py:1377} INFO - Executing <Task(_PythonDecoratedOperator): load_group_log> on 2022-10-26 11:15:00+00:00
[2022-10-26 11:30:08,615] {standard_task_runner.py:52} INFO - Started process 1578 to run task
[2022-10-26 11:30:08,618] {standard_task_runner.py:79} INFO - Running: ['airflow', 'tasks', 'run', 'dag', 'load_group_log', 'scheduled__2022-10-26T11:15:00+00:00', '--job-id', '94', '--raw', '--subdir', 'DAGS_FOLDER/test.py', '--cfg-path', '/tmp/tmpzlqt6gcs', '--error-file', '/tmp/tmpzr4lqega']
[2022-10-26 11:30:08,618] {standard_task_runner.py:80} INFO - Job 94: Subtask load_group_log
[2022-10-26 11:30:08,674] {task_command.py:369} INFO - Running <TaskInstance: dag.load_group_log scheduled__2022-10-26T11:15:00+00:00 [running]> on host cf01c04ee00d
[2022-10-26 11:30:08,740] {taskinstance.py:1569} INFO - Exporting the following env vars:
AIRFLOW_CTX_DAG_OWNER=airflow
AIRFLOW_CTX_DAG_ID=dag
AIRFLOW_CTX_TASK_ID=load_group_log
AIRFLOW_CTX_EXECUTION_DATE=2022-10-26T11:15:00+00:00
AIRFLOW_CTX_TRY_NUMBER=1
AIRFLOW_CTX_DAG_RUN_ID=scheduled__2022-10-26T11:15:00+00:00
[2022-10-26 11:30:08,781] {taskinstance.py:1889} ERROR - Task failed with exception
Traceback (most recent call last):
  File "/usr/local/lib/python3.8/dist-packages/airflow/decorators/base.py", line 179, in execute
    return_value = super().execute(context)
  File "/usr/local/lib/python3.8/dist-packages/airflow/operators/python.py", line 171, in execute
    return_value = self.execute_callable()
  File "/usr/local/lib/python3.8/dist-packages/airflow/operators/python.py", line 189, in execute_callable
    return self.python_callable(*self.op_args, **self.op_kwargs)
  File "/lessons/dags/test.py", line 63, in load_group_log
    loads('group_log')
  File "/lessons/dags/test.py", line 39, in loads
    with open(f'../data/{str1}.csv', "rb") as fs:
FileNotFoundError: [Errno 2] No such file or directory: '../data/group_log.csv'
[2022-10-26 11:30:08,794] {taskinstance.py:1395} INFO - Marking task as FAILED. dag_id=dag, task_id=load_group_log, execution_date=20221026T111500, start_date=20221026T113008, end_date=20221026T113008
[2022-10-26 11:30:08,804] {standard_task_runner.py:92} ERROR - Failed to execute job 94 for task load_group_log ([Errno 2] No such file or directory: '../data/group_log.csv'; 1578)
[2022-10-26 11:30:08,831] {local_task_job.py:156} INFO - Task exited with return code 1
[2022-10-26 11:30:08,864] {local_task_job.py:273} INFO - 0 downstream tasks scheduled from follow-on schedule check
