[2022-10-26 10:39:01,283] {taskinstance.py:1159} INFO - Dependencies all met for <TaskInstance: extract.load_group_log manual__2022-10-26T10:38:54.728916+00:00 [queued]>
[2022-10-26 10:39:01,293] {taskinstance.py:1159} INFO - Dependencies all met for <TaskInstance: extract.load_group_log manual__2022-10-26T10:38:54.728916+00:00 [queued]>
[2022-10-26 10:39:01,293] {taskinstance.py:1356} INFO - 
--------------------------------------------------------------------------------
[2022-10-26 10:39:01,293] {taskinstance.py:1357} INFO - Starting attempt 1 of 1
[2022-10-26 10:39:01,294] {taskinstance.py:1358} INFO - 
--------------------------------------------------------------------------------
[2022-10-26 10:39:01,309] {taskinstance.py:1377} INFO - Executing <Task(PythonOperator): load_group_log> on 2022-10-26 10:38:54.728916+00:00
[2022-10-26 10:39:01,311] {standard_task_runner.py:52} INFO - Started process 587 to run task
[2022-10-26 10:39:01,314] {standard_task_runner.py:79} INFO - Running: ['airflow', 'tasks', 'run', 'extract', 'load_group_log', 'manual__2022-10-26T10:38:54.728916+00:00', '--job-id', '76', '--raw', '--subdir', 'DAGS_FOLDER/extract.py', '--cfg-path', '/tmp/tmpwpz__bei', '--error-file', '/tmp/tmpoy_c8jvw']
[2022-10-26 10:39:01,315] {standard_task_runner.py:80} INFO - Job 76: Subtask load_group_log
[2022-10-26 10:39:01,379] {task_command.py:369} INFO - Running <TaskInstance: extract.load_group_log manual__2022-10-26T10:38:54.728916+00:00 [running]> on host cf01c04ee00d
[2022-10-26 10:39:01,447] {taskinstance.py:1569} INFO - Exporting the following env vars:
AIRFLOW_CTX_DAG_OWNER=airflow
AIRFLOW_CTX_DAG_ID=extract
AIRFLOW_CTX_TASK_ID=load_group_log
AIRFLOW_CTX_EXECUTION_DATE=2022-10-26T10:38:54.728916+00:00
AIRFLOW_CTX_TRY_NUMBER=1
AIRFLOW_CTX_DAG_RUN_ID=manual__2022-10-26T10:38:54.728916+00:00
[2022-10-26 10:39:01,490] {taskinstance.py:1889} ERROR - Task failed with exception
Traceback (most recent call last):
  File "/usr/local/lib/python3.8/dist-packages/airflow/operators/python.py", line 171, in execute
    return_value = self.execute_callable()
  File "/usr/local/lib/python3.8/dist-packages/airflow/operators/python.py", line 189, in execute_callable
    return self.python_callable(*self.op_args, **self.op_kwargs)
  File "/lessons/dags/extract.py", line 40, in loads
    with open(f'../data/{str1}.csv', "rb") as fs:
FileNotFoundError: [Errno 2] No such file or directory: '../data/group_log.csv'
[2022-10-26 10:39:01,505] {taskinstance.py:1395} INFO - Marking task as FAILED. dag_id=extract, task_id=load_group_log, execution_date=20221026T103854, start_date=20221026T103901, end_date=20221026T103901
[2022-10-26 10:39:01,517] {standard_task_runner.py:92} ERROR - Failed to execute job 76 for task load_group_log ([Errno 2] No such file or directory: '../data/group_log.csv'; 587)
[2022-10-26 10:39:01,528] {local_task_job.py:156} INFO - Task exited with return code 1
[2022-10-26 10:39:01,570] {local_task_job.py:273} INFO - 0 downstream tasks scheduled from follow-on schedule check
