[2022-10-26 14:38:54,495] {taskinstance.py:1159} INFO - Dependencies all met for <TaskInstance: dag.fetch_file manual__2022-10-26T14:38:53.028722+00:00 [queued]>
[2022-10-26 14:38:54,503] {taskinstance.py:1159} INFO - Dependencies all met for <TaskInstance: dag.fetch_file manual__2022-10-26T14:38:53.028722+00:00 [queued]>
[2022-10-26 14:38:54,504] {taskinstance.py:1356} INFO - 
--------------------------------------------------------------------------------
[2022-10-26 14:38:54,504] {taskinstance.py:1357} INFO - Starting attempt 1 of 1
[2022-10-26 14:38:54,505] {taskinstance.py:1358} INFO - 
--------------------------------------------------------------------------------
[2022-10-26 14:38:54,517] {taskinstance.py:1377} INFO - Executing <Task(_PythonDecoratedOperator): fetch_file> on 2022-10-26 14:38:53.028722+00:00
[2022-10-26 14:38:54,519] {standard_task_runner.py:52} INFO - Started process 5060 to run task
[2022-10-26 14:38:54,521] {standard_task_runner.py:79} INFO - Running: ['airflow', 'tasks', 'run', 'dag', 'fetch_file', 'manual__2022-10-26T14:38:53.028722+00:00', '--job-id', '146', '--raw', '--subdir', 'DAGS_FOLDER/test.py', '--cfg-path', '/tmp/tmp7c1mgifa', '--error-file', '/tmp/tmp83powyeh']
[2022-10-26 14:38:54,522] {standard_task_runner.py:80} INFO - Job 146: Subtask fetch_file
[2022-10-26 14:38:54,578] {task_command.py:369} INFO - Running <TaskInstance: dag.fetch_file manual__2022-10-26T14:38:53.028722+00:00 [running]> on host cf01c04ee00d
[2022-10-26 14:38:54,647] {taskinstance.py:1569} INFO - Exporting the following env vars:
AIRFLOW_CTX_DAG_OWNER=airflow
AIRFLOW_CTX_DAG_ID=dag
AIRFLOW_CTX_TASK_ID=fetch_file
AIRFLOW_CTX_EXECUTION_DATE=2022-10-26T14:38:53.028722+00:00
AIRFLOW_CTX_TRY_NUMBER=1
AIRFLOW_CTX_DAG_RUN_ID=manual__2022-10-26T14:38:53.028722+00:00
[2022-10-26 14:38:55,149] {taskinstance.py:1889} ERROR - Task failed with exception
Traceback (most recent call last):
  File "/usr/local/lib/python3.8/dist-packages/airflow/decorators/base.py", line 179, in execute
    return_value = super().execute(context)
  File "/usr/local/lib/python3.8/dist-packages/airflow/operators/python.py", line 171, in execute
    return_value = self.execute_callable()
  File "/usr/local/lib/python3.8/dist-packages/airflow/operators/python.py", line 189, in execute_callable
    return self.python_callable(*self.op_args, **self.op_kwargs)
  File "/lessons/dags/test.py", line 63, in fetch_file
    fetch_s3_file('data-bucket', 'group_log.csv')
  File "/lessons/dags/test.py", line 24, in fetch_s3_file
    s3_client.download_file(
  File "/usr/local/lib/python3.8/dist-packages/boto3/s3/inject.py", line 190, in download_file
    return transfer.download_file(
  File "/usr/local/lib/python3.8/dist-packages/boto3/s3/transfer.py", line 320, in download_file
    future.result()
  File "/usr/local/lib/python3.8/dist-packages/s3transfer/futures.py", line 103, in result
    return self._coordinator.result()
  File "/usr/local/lib/python3.8/dist-packages/s3transfer/futures.py", line 266, in result
    raise self._exception
  File "/usr/local/lib/python3.8/dist-packages/s3transfer/tasks.py", line 139, in __call__
    return self._execute_main(kwargs)
  File "/usr/local/lib/python3.8/dist-packages/s3transfer/tasks.py", line 162, in _execute_main
    return_value = self._main(**kwargs)
  File "/usr/local/lib/python3.8/dist-packages/s3transfer/download.py", line 642, in _main
    fileobj.seek(offset)
  File "/usr/local/lib/python3.8/dist-packages/s3transfer/utils.py", line 378, in seek
    self._open_if_needed()
  File "/usr/local/lib/python3.8/dist-packages/s3transfer/utils.py", line 361, in _open_if_needed
    self._fileobj = self._open_function(self._filename, self._mode)
  File "/usr/local/lib/python3.8/dist-packages/s3transfer/utils.py", line 272, in open
    return open(filename, mode)
FileNotFoundError: [Errno 2] No such file or directory: 'data/group_log.csv.f726e1Cc'
[2022-10-26 14:38:55,165] {taskinstance.py:1395} INFO - Marking task as FAILED. dag_id=dag, task_id=fetch_file, execution_date=20221026T143853, start_date=20221026T143854, end_date=20221026T143855
[2022-10-26 14:38:55,176] {standard_task_runner.py:92} ERROR - Failed to execute job 146 for task fetch_file ([Errno 2] No such file or directory: 'data/group_log.csv.f726e1Cc'; 5060)
[2022-10-26 14:38:55,216] {local_task_job.py:156} INFO - Task exited with return code 1
[2022-10-26 14:38:55,259] {local_task_job.py:273} INFO - 0 downstream tasks scheduled from follow-on schedule check
