[2022-10-26 10:50:43,355] {taskinstance.py:1159} INFO - Dependencies all met for <TaskInstance: dag.fetch_s3_file manual__2022-10-26T10:50:41.899869+00:00 [queued]>
[2022-10-26 10:50:43,363] {taskinstance.py:1159} INFO - Dependencies all met for <TaskInstance: dag.fetch_s3_file manual__2022-10-26T10:50:41.899869+00:00 [queued]>
[2022-10-26 10:50:43,364] {taskinstance.py:1356} INFO - 
--------------------------------------------------------------------------------
[2022-10-26 10:50:43,364] {taskinstance.py:1357} INFO - Starting attempt 1 of 1
[2022-10-26 10:50:43,365] {taskinstance.py:1358} INFO - 
--------------------------------------------------------------------------------
[2022-10-26 10:50:43,377] {taskinstance.py:1377} INFO - Executing <Task(_PythonDecoratedOperator): fetch_s3_file> on 2022-10-26 10:50:41.899869+00:00
[2022-10-26 10:50:43,379] {standard_task_runner.py:52} INFO - Started process 780 to run task
[2022-10-26 10:50:43,382] {standard_task_runner.py:79} INFO - Running: ['airflow', 'tasks', 'run', 'dag', 'fetch_s3_file', 'manual__2022-10-26T10:50:41.899869+00:00', '--job-id', '80', '--raw', '--subdir', 'DAGS_FOLDER/test.py', '--cfg-path', '/tmp/tmpzfeoiykf', '--error-file', '/tmp/tmpny5d4m4o']
[2022-10-26 10:50:43,383] {standard_task_runner.py:80} INFO - Job 80: Subtask fetch_s3_file
[2022-10-26 10:50:43,437] {task_command.py:369} INFO - Running <TaskInstance: dag.fetch_s3_file manual__2022-10-26T10:50:41.899869+00:00 [running]> on host cf01c04ee00d
[2022-10-26 10:50:43,506] {taskinstance.py:1569} INFO - Exporting the following env vars:
AIRFLOW_CTX_DAG_OWNER=airflow
AIRFLOW_CTX_DAG_ID=dag
AIRFLOW_CTX_TASK_ID=fetch_s3_file
AIRFLOW_CTX_EXECUTION_DATE=2022-10-26T10:50:41.899869+00:00
AIRFLOW_CTX_TRY_NUMBER=1
AIRFLOW_CTX_DAG_RUN_ID=manual__2022-10-26T10:50:41.899869+00:00
[2022-10-26 10:50:43,507] {taskinstance.py:1889} ERROR - Task failed with exception
Traceback (most recent call last):
  File "/usr/local/lib/python3.8/dist-packages/airflow/decorators/base.py", line 179, in execute
    return_value = super().execute(context)
  File "/usr/local/lib/python3.8/dist-packages/airflow/operators/python.py", line 171, in execute
    return_value = self.execute_callable()
  File "/usr/local/lib/python3.8/dist-packages/airflow/operators/python.py", line 189, in execute_callable
    return self.python_callable(*self.op_args, **self.op_kwargs)
  File "/lessons/dags/test.py", line 59, in fetch_s3_file
    fetch_s3_file('data-bucket', 'group_log.csv')
TypeError: 'XComArg' object is not callable
[2022-10-26 10:50:43,521] {taskinstance.py:1395} INFO - Marking task as FAILED. dag_id=dag, task_id=fetch_s3_file, execution_date=20221026T105041, start_date=20221026T105043, end_date=20221026T105043
[2022-10-26 10:50:43,531] {standard_task_runner.py:92} ERROR - Failed to execute job 80 for task fetch_s3_file ('XComArg' object is not callable; 780)
[2022-10-26 10:50:43,555] {local_task_job.py:156} INFO - Task exited with return code 1
[2022-10-26 10:50:43,597] {local_task_job.py:273} INFO - 0 downstream tasks scheduled from follow-on schedule check
