[2022-10-26 09:57:57,808] {taskinstance.py:1159} INFO - Dependencies all met for <TaskInstance: extract.load_group_log manual__2022-10-26T09:57:50.883934+00:00 [queued]>
[2022-10-26 09:57:57,815] {taskinstance.py:1159} INFO - Dependencies all met for <TaskInstance: extract.load_group_log manual__2022-10-26T09:57:50.883934+00:00 [queued]>
[2022-10-26 09:57:57,815] {taskinstance.py:1356} INFO - 
--------------------------------------------------------------------------------
[2022-10-26 09:57:57,816] {taskinstance.py:1357} INFO - Starting attempt 1 of 1
[2022-10-26 09:57:57,816] {taskinstance.py:1358} INFO - 
--------------------------------------------------------------------------------
[2022-10-26 09:57:57,829] {taskinstance.py:1377} INFO - Executing <Task(PythonOperator): load_group_log> on 2022-10-26 09:57:50.883934+00:00
[2022-10-26 09:57:57,831] {standard_task_runner.py:52} INFO - Started process 1549 to run task
[2022-10-26 09:57:57,833] {standard_task_runner.py:79} INFO - Running: ['airflow', 'tasks', 'run', 'extract', 'load_group_log', 'manual__2022-10-26T09:57:50.883934+00:00', '--job-id', '68', '--raw', '--subdir', 'DAGS_FOLDER/extract.py', '--cfg-path', '/tmp/tmpx3_po4ju', '--error-file', '/tmp/tmppl4ej558']
[2022-10-26 09:57:57,834] {standard_task_runner.py:80} INFO - Job 68: Subtask load_group_log
[2022-10-26 09:57:57,885] {task_command.py:369} INFO - Running <TaskInstance: extract.load_group_log manual__2022-10-26T09:57:50.883934+00:00 [running]> on host cf01c04ee00d
[2022-10-26 09:57:57,952] {taskinstance.py:1569} INFO - Exporting the following env vars:
AIRFLOW_CTX_DAG_OWNER=airflow
AIRFLOW_CTX_DAG_ID=extract
AIRFLOW_CTX_TASK_ID=load_group_log
AIRFLOW_CTX_EXECUTION_DATE=2022-10-26T09:57:50.883934+00:00
AIRFLOW_CTX_TRY_NUMBER=1
AIRFLOW_CTX_DAG_RUN_ID=manual__2022-10-26T09:57:50.883934+00:00
[2022-10-26 09:57:57,953] {taskinstance.py:1889} ERROR - Task failed with exception
Traceback (most recent call last):
  File "/usr/local/lib/python3.8/dist-packages/airflow/operators/python.py", line 171, in execute
    return_value = self.execute_callable()
  File "/usr/local/lib/python3.8/dist-packages/airflow/operators/python.py", line 189, in execute_callable
    return self.python_callable(*self.op_args, **self.op_kwargs)
  File "/lessons/dags/extract.py", line 33, in loads
    conn_info = connect(
NameError: name 'connect' is not defined
[2022-10-26 09:57:57,968] {taskinstance.py:1395} INFO - Marking task as FAILED. dag_id=extract, task_id=load_group_log, execution_date=20221026T095750, start_date=20221026T095757, end_date=20221026T095757
[2022-10-26 09:57:57,978] {standard_task_runner.py:92} ERROR - Failed to execute job 68 for task load_group_log (name 'connect' is not defined; 1549)
[2022-10-26 09:57:58,005] {local_task_job.py:156} INFO - Task exited with return code 1
[2022-10-26 09:57:58,039] {local_task_job.py:273} INFO - 0 downstream tasks scheduled from follow-on schedule check
